} catch (TheCheckedException e) {
      throw new AssertionError(); // 일어날 수 없다!
}
